Workbook

Sheet Read Me
A1: Microsoft consumer AI: forecast backtest and monetization business case
A2: Outside-in analysis built only from public filings and published prices. Not affiliated with Microsoft. October 2026.
A4: Question | B4: How should Microsoft grow consumer Copilot revenue over FY27 to FY29: upsell the Microsoft 365 consumer ladder, launch a low-price AI tier, or lean harder on ads in free Copilot?
A5: Data | B5: Eight quarters of revenue by business line (FY25 Q1 to FY26 Q4) from Microsoft's September 2026 restatement filing, plus disclosed growth metrics.
A6: Backtest | B6: How accurate Microsoft's own search-ads guidance has been, against a naive method and a bias-corrected method, quarter by quarter.
A7: FY27 Q1 Forecast | B7: Forecast for the quarter ending September 2026, published before Microsoft reports it in late October 2026.
A8: Business Case | B8: Three options sized over FY27 to FY29: revenue, cost, gross profit and NPV.
A9: Sensitivity | B9: How the two uncertain options change with their key drivers, compared with the low-risk option.
A10: Sources | B10: Every hardcoded number and where it came from.
A12: Colour key
A13: 1,234 | B13: Blue: hardcoded input or assumption. Change these to test your own view.
A14: 1,234 | B14: Green: pulled from another sheet.
A15: 1,234 | B15: Black: formula.
B16: Yellow fill: key assumption with the most influence on the answer.
A18: Units | B18: $ millions unless the row label says otherwise. Growth rates are year over year.
A19: Fiscal calendar | B19: Microsoft's fiscal year runs July 1 to June 30. FY26 = July 2025 to June 2026. Q1 = Jul-Sep, Q2 = Oct-Dec, Q3 = Jan-Mar, Q4 = Apr-Jun.

Sheet Data
A1: Quarterly revenue by business line ($M)
A2: Source: Microsoft Form 8-K, 'FY27 Segments and Investor Metrics', September 2026 (Exhibit 99.1), and FY26 earnings releases. See Sources tab.
A4: Metric | B4: FY25 Q1 Jul-Sep 2024 | C4: FY25 Q2 Oct-Dec 2024 | D4: FY25 Q3 Jan-Mar 2025 | E4: FY25 Q4 Apr-Jun 2025 | F4: FY26 Q1 Jul-Sep 2025 | G4: FY26 Q2 Oct-Dec 2025 | H4: FY26 Q3 Jan-Mar 2026 | I4: FY26 Q4 Apr-Jun 2026 | J4: FY25 Jul 2024-Jun 2025 | K4: FY26 Jul 2025-Jun 2026 | L4: Note
A5: Search advertising revenue, as reported | B5: 3225 | C5: 3558 | D5: 3504 | E5: 3591 | F5: 3697 | G5: 3812 | H5: 3808 | I5: 3859 | J5: =SUM(B5:E5) -> 13878 | K5: =SUM(F5:I5) -> 15176 | L5: Bing, Copilot, Edge and third-party affiliates; gross of traffic acquisition costs
A6: Microsoft 365 consumer products and cloud | B6: 1727 | C6: 1821 | D6: 1821 | E6: 2035 | F6: 2204 | G6: 2305 | H6: 2297 | I6: 2369 | J6: =SUM(B6:E6) -> 7404 | K6: =SUM(F6:I6) -> 9175 | L6: Personal, Family, Premium subscriptions and Office consumer licences
A7: Windows and devices | B7: 4329 | C7: 4512 | D7: 4144 | E7: 4329 | F7: 4551 | G7: 4479 | H7: 4041 | I7: 4013 | J7: =SUM(B7:E7) -> 17314 | K7: =SUM(F7:I7) -> 17084
A8: XBOX | B8: 5621 | C8: 6581 | D8: 5721 | E8: 5532 | F8: 5508 | G8: 5958 | H8: 5341 | I8: 4983 | J8: =SUM(B8:E8) -> 23455 | K8: =SUM(F8:I8) -> 21790
A9: Devices and Consumer segment, restated | B9: 15109 | C9: 16866 | D9: 15303 | E9: 15663 | F9: 16001 | G9: 16832 | H9: 15448 | I9: 15431 | J9: =SUM(B9:E9) -> 62941 | K9: =SUM(F9:I9) -> 63712 | L9: New FY27 segment: search and advertising, XBOX, Windows OEM and devices
A10: Search and advertising, restated | B10: 5159 | C10: 5773 | D10: 5437 | E10: 5802 | F10: 5942 | G10: 6393 | H10: 6065 | I10: 6435 | J10: =SUM(B10:E10) -> 22171 | K10: =SUM(F10:I10) -> 24835 | L10: Adds LinkedIn Marketing Solutions and Premium Subscriptions
A12: Year-over-year growth
A13: Metric | B13: FY25 Q1 Jul-Sep 2024 | C13: FY25 Q2 Oct-Dec 2024 | D13: FY25 Q3 Jan-Mar 2025 | E13: FY25 Q4 Apr-Jun 2025 | F13: FY26 Q1 Jul-Sep 2025 | G13: FY26 Q2 Oct-Dec 2025 | H13: FY26 Q3 Jan-Mar 2026 | I13: FY26 Q4 Apr-Jun 2026 | J13: FY25 Jul 2024-Jun 2025 | K13: FY26 Jul 2025-Jun 2026 | L13: Note
A14: Search advertising revenue, as reported | F14: =F5/B5-1 -> 0.14635659 | G14: =G5/C5-1 -> 0.07138842 | H14: =H5/D5-1 -> 0.086757991 | I14: =I5/E5-1 -> 0.074631022 | K14: =K5/J5-1 -> 0.093529327
A15: Microsoft 365 consumer products and cloud | F15: =F6/B6-1 -> 0.27620151 | G15: =G6/C6-1 -> 0.26578803 | H15: =H6/D6-1 -> 0.26139484 | I15: =I6/E6-1 -> 0.16412776 | K15: =K6/J6-1 -> 0.23919503
A16: Windows and devices | F16: =F7/B7-1 -> 0.051282051 | G16: =G7/C7-1 -> -0.0073138298 | H16: =H7/D7-1 -> -0.024855212 | I16: =I7/E7-1 -> -0.072996073 | K16: =K7/J7-1 -> -0.013284048
A17: XBOX | F17: =F8/B8-1 -> -0.020103184 | G17: =G8/C8-1 -> -0.094666464 | H17: =H8/D8-1 -> -0.066421954 | I17: =I8/E8-1 -> -0.099240781 | K17: =K8/J8-1 -> -0.070986996
A18: Devices and Consumer segment, restated | F18: =F9/B9-1 -> 0.05903766 | G18: =G9/C9-1 -> -0.00201589 | H18: =H9/D9-1 -> 0.0094752663 | I18: =I9/E9-1 -> -0.014811977 | K18: =K9/J9-1 -> 0.012249567
A19: Search and advertising, restated | F19: =F10/B10-1 -> 0.1517736 | G19: =G10/C10-1 -> 0.1073965 | H19: =H10/D10-1 -> 0.11550487 | I19: =I10/E10-1 -> 0.10910031 | K19: =K10/J10-1 -> 0.12015696
A21: Disclosed growth metrics
A22: Metric | B22: FY25 Q1 Jul-Sep 2024 | C22: FY25 Q2 Oct-Dec 2024 | D22: FY25 Q3 Jan-Mar 2025 | E22: FY25 Q4 Apr-Jun 2025 | F22: FY26 Q1 Jul-Sep 2025 | G22: FY26 Q2 Oct-Dec 2025 | H22: FY26 Q3 Jan-Mar 2026 | I22: FY26 Q4 Apr-Jun 2026 | J22: FY25 Jul 2024-Jun 2025 | K22: FY26 Jul 2025-Jun 2026 | L22: Note
A23: Search ad revenue ex-TAC growth, as reported basis | D23: 0.21 | E23: 0.21 | F23: 0.16 | G23: 0.1 | H23: 0.12 | I23: 0.1 | K23: 0.12 | L23: Earnings releases; FY26 restatement filing
A24: Search and advertising ex-TAC growth, restated basis | F24: 0.16 | G24: 0.13 | H24: 0.14 | I24: 0.13 | K24: 0.14 | L24: September 2026 restatement filing
A25: Microsoft 365 consumer cloud revenue growth | G25: 0.29 | I25: 0.24 | L25: FY26 Q2 and Q4 earnings calls; Q1 and Q3 not stated in sources used
A26: Microsoft 365 consumer subscription growth | G26: 0.06 | L26: FY26 Q2 earnings call: revenue growth driven by revenue per subscriber

Sheet Backtest
A1: How good is Microsoft's search-ads guidance? Backtest, FY25 Q4 to FY26 Q4
A2: Search ad revenue ex-TAC growth, as reported basis. Guidance is the wording given on the prior quarter's earnings call (Microsoft investor relations transcripts), converted to a numeric range.
A4: Quarter | B4: Guidance given (words) | C4: Guide low | D4: Guide high | E4: Guide midpoint | F4: Actual growth | G4: Naive forecast (prior qtr actual) | H4: Guidance error (mid - actual) | I4: Naive error | J4: Beat vs midpoint (actual - mid) | K4: Bias-corrected forecast | L4: Bias-corrected error | M4: |Guidance error| | N4: |Naive error| | O4: |Bias-corrected error|
A5: FY25 Q4 (Apr-Jun 2025) | B5: High teens | C5: 0.17 | D5: 0.19 | E5: =IF(AND(ISNUMBER(C5),ISNUMBER(D5)),(C5+D5)/2,"") -> 0.18 | F5: =Data!E23 -> 0.21 | G5: =Data!D23 -> 0.21 | H5: =IF(ISNUMBER(E5),E5-F5,"") -> -0.03 | I5: =G5-F5 -> 0 | J5: =IF(ISNUMBER(E5),F5-E5,"") -> 0.03 | K5: ="" | L5: =IF(ISNUMBER(K5),K5-F5,"") | M5: =IF(ISNUMBER(H5),ABS(H5),"") -> 0.03 | N5: =ABS(I5) -> 0 | O5: =IF(ISNUMBER(L5),ABS(L5),"")
A6: FY26 Q1 (Jul-Sep 2025) | B6: Low- to mid-teens | C6: 0.11 | D6: 0.15 | E6: =IF(AND(ISNUMBER(C6),ISNUMBER(D6)),(C6+D6)/2,"") -> 0.13 | F6: =Data!F23 -> 0.16 | G6: =F5 -> 0.21 | H6: =IF(ISNUMBER(E6),E6-F6,"") -> -0.03 | I6: =G6-F6 -> 0.05 | J6: =IF(ISNUMBER(E6),F6-E6,"") -> 0.03 | K6: =IF(AND(ISNUMBER(E6),COUNT(J$5:J5)>0),E6+AVERAGE(J$5:J5),"") -> 0.16 | L6: =IF(ISNUMBER(K6),K6-F6,"") -> 0 | M6: =IF(ISNUMBER(H6),ABS(H6),"") -> 0.03 | N6: =ABS(I6) -> 0.05 | O6: =IF(ISNUMBER(L6),ABS(L6),"") -> 0
A7: FY26 Q2 (Oct-Dec 2025) | B7: Low double digits | C7: 0.1 | D7: 0.12 | E7: =IF(AND(ISNUMBER(C7),ISNUMBER(D7)),(C7+D7)/2,"") -> 0.11 | F7: =Data!G23 -> 0.1 | G7: =F6 -> 0.16 | H7: =IF(ISNUMBER(E7),E7-F7,"") -> 0.01 | I7: =G7-F7 -> 0.06 | J7: =IF(ISNUMBER(E7),F7-E7,"") -> -0.01 | K7: =IF(AND(ISNUMBER(E7),COUNT(J$5:J6)>0),E7+AVERAGE(J$5:J6),"") -> 0.14 | L7: =IF(ISNUMBER(K7),K7-F7,"") -> 0.04 | M7: =IF(ISNUMBER(H7),ABS(H7),"") -> 0.01 | N7: =ABS(I7) -> 0.06 | O7: =IF(ISNUMBER(L7),ABS(L7),"") -> 0.04
A8: FY26 Q3 (Jan-Mar 2026) | B8: High single digits | C8: 0.07 | D8: 0.09 | E8: =IF(AND(ISNUMBER(C8),ISNUMBER(D8)),(C8+D8)/2,"") -> 0.08 | F8: =Data!H23 -> 0.12 | G8: =F7 -> 0.1 | H8: =IF(ISNUMBER(E8),E8-F8,"") -> -0.04 | I8: =G8-F8 -> -0.02 | J8: =IF(ISNUMBER(E8),F8-E8,"") -> 0.04 | K8: =IF(AND(ISNUMBER(E8),COUNT(J$5:J7)>0),E8+AVERAGE(J$5:J7),"") -> 0.096666667 | L8: =IF(ISNUMBER(K8),K8-F8,"") -> -0.023333333 | M8: =IF(ISNUMBER(H8),ABS(H8),"") -> 0.04 | N8: =ABS(I8) -> 0.02 | O8: =IF(ISNUMBER(L8),ABS(L8),"") -> 0.023333333
A9: FY26 Q4 (Apr-Jun 2026) | B9: High single digits | C9: 0.07 | D9: 0.09 | E9: =IF(AND(ISNUMBER(C9),ISNUMBER(D9)),(C9+D9)/2,"") -> 0.08 | F9: =Data!I23 -> 0.1 | G9: =F8 -> 0.12 | H9: =IF(ISNUMBER(E9),E9-F9,"") -> -0.02 | I9: =G9-F9 -> 0.02 | J9: =IF(ISNUMBER(E9),F9-E9,"") -> 0.02 | K9: =IF(AND(ISNUMBER(E9),COUNT(J$5:J8)>0),E9+AVERAGE(J$5:J8),"") -> 0.1025 | L9: =IF(ISNUMBER(K9),K9-F9,"") -> 0.0025 | M9: =IF(ISNUMBER(H9),ABS(H9),"") -> 0.02 | N9: =ABS(I9) -> 0.02 | O9: =IF(ISNUMBER(L9),ABS(L9),"") -> 0.0025
A12: Summary
A13: Quarters with guidance found | E13: =COUNT(M5:M9) -> 5
A14: Mean absolute error, guidance midpoint | E14: =AVERAGE(M5:M9) -> 0.026
A15: Mean absolute error, naive method (same quarters) | E15: =SUMPRODUCT(ISNUMBER(M5:M9)*N5:N9)/COUNT(M5:M9) -> 0.03
A16: Average beat vs guidance midpoint | E16: =AVERAGE(J5:J9) -> 0.022
A17: Quarters with a bias-corrected forecast (needs a prior beat) | E17: =COUNT(O5:O9) -> 4
A18: Mean absolute error, bias-corrected guidance | E18: =AVERAGE(O5:O9) -> 0.016458333
A19: Mean absolute error, raw guidance (same quarters) | E19: =AVERAGEIFS(M5:M9,O5:O9,">=0") -> 0.025
A20: Mean absolute error, naive method (same quarters) | E20: =AVERAGEIFS(N5:N9,O5:O9,">=0") -> 0.0375
A22: Reading: the actual result came in above the guidance midpoint in four of five quarters. The exception, FY26 Q2, Microsoft described as slightly below expectations due to execution challenges. Adding the average past beat to the midpoint reduced the error, but five quarters is a small sample: a pattern to watch, not a proven rule.

Sheet FY27 Q1 Forecast
A1: FY27 Q1 forecast (quarter ending September 30, 2026)
A2: Made before Microsoft reports in late October 2026. Guidance from the July 29, 2026 call and the September 2026 restatement filing.
A4: Search advertising | B4: As reported basis | C4: Restated basis | D4: Note
A5: Guidance, words | B5: Mid-single digits | C5: Mid- to high-single digits | D5: Ex-TAC growth
A6: Guide low | B6: 0.04 | C6: 0.06 | D6: Interpretation of the guidance wording
A7: Guide high | B7: 0.06 | C7: 0.08
A8: Guide midpoint | B8: =(B6+B7)/2 -> 0.05 | C8: =(C6+C7)/2 -> 0.07
A9: Average historical beat (Backtest) | B9: =Backtest!E16 -> 0.022 | C9: =B9 -> 0.022 | D9: Restated basis assumes the same beat
A10: Bias-corrected forecast, ex-TAC growth | B10: =B8+B9 -> 0.072 | C10: =C8+C9 -> 0.092
A11: Naive forecast (FY26 Q4 actual) | B11: =Data!I23 -> 0.1 | C11: =Data!I24 -> 0.13
A13: Implied reported search advertising revenue
A14: FY26 Q1 revenue ($M) | B14: =Data!F5 -> 3697
A15: Gap: reported growth minus ex-TAC growth, FY26 | B15: =Data!K14-Data!K23 -> -0.026470673 | D15: TAC grew faster than revenue in FY26
A16: Forecast FY27 Q1 revenue ($M) | B16: =B14*(1+B10+B15) -> 3865.3219
A18: Microsoft 365 consumer
A19: Guidance: consumer cloud growth | B19: Mid-teens
A20: Guide low | B20: 0.14
A21: Guide high | B21: 0.16
A22: Guide midpoint | B22: =(B20+B21)/2 -> 0.15
A23: FY26 Q1 products and cloud revenue ($M) | B23: =Data!F6 -> 2204
A24: Forecast FY27 Q1 revenue ($M) | B24: =B23*(1+B22) -> 2534.6 | D24: Approximation: guidance covers the cloud portion only
A26: Devices and Consumer segment (restated)
A27: Guidance low ($M) | B27: 14700
A28: Guidance high ($M) | B28: 15200
A29: FY26 Q1 restated ($M) | B29: =Data!F9 -> 16001
A30: Implied growth at guidance midpoint | B30: =((B27+B28)/2)/B29-1 -> -0.065683395 | D30: Decline driven by Windows OEM (guided down low-twenties) and XBOX

Sheet Business Case
A1: Consumer Copilot monetization: three options, FY27 to FY29
A2: Incremental to today's plan. Options can be combined; each is sized on its own so they can be compared.
A4: Shared inputs
A5: Microsoft 365 consumer revenue, FY26 ($M) | B5: =Data!K6 -> 9175 | D5: Data tab
A6: Cloud share of that revenue | B6: 0.9 | D6: Assumption: excludes Office consumer licences
A7: Blended revenue per paid subscriber per year ($) | B7: 95 | D7: Assumption: mix of Personal, Family, Premium, legacy plans, discounts
A8: Implied paid consumer subscribers (M) | B8: =B5*B6/B7 -> 86.921053 | D8: Microsoft stopped disclosing this count in FY26 Q1, so it is derived
A9: Subscriber growth per year | B9: 0.04 | D9: Assumption
A10: Free Copilot consumer monthly users, FY26 (M) | B10: 300 | D10: Third-party estimates range 218M to 420M depending on surfaces counted
A11: Monthly user growth per year | B11: 0.1 | D11: Assumption
A12: Discount rate | B12: 0.09 | D12: Assumption
A13: Bing monthly users (M) | B13: 1000 | D13: Disclosed on the FY26 Q3 earnings call
A14: Search ad revenue per Bing user per year ($) | B14: =Data!K5/B13 -> 15.176 | D14: Benchmark for ad yield
A16: Option A: upsell the Microsoft 365 consumer ladder to Premium
A17: Premium price per year ($) | B17: 199.99 | D17: Published US price
A18: Family price per year ($) | B18: 129.99 | D18: Published US price
A19: Price step per upgrade ($) | B19: =B17-B18 -> 70
A20: Share of list price realised | B20: 0.85 | D20: Assumption: promotions, regional pricing
A21: Premium share of subscribers today | B21: 0.04 | D21: Assumption
A22: Added AI cost per upgraded subscriber per year ($) | B22: 18 | D22: Assumption: higher usage limits
A23: Premium share of subscribers, target | C23: 0.06 | D23: 0.08 | E23: 0.1
A25: Option B: launch a low-price AI tier (no Office apps)
A26: Price per month ($) | B26: 7.99 | D26: Matches Google AI Plus and ChatGPT Go
A27: Price per year ($) | B27: =B26*12 -> 95.88
A28: Cost to serve per subscriber per year ($) | B28: 30 | D28: Assumption
A29: Acquisition cost per new subscriber ($) | B29: 20 | D29: Assumption
A30: Share of new subscribers who downgrade from Personal | B30: 0.2 | D30: Assumption
A31: Personal price per year ($) | B31: 99.99 | D31: Published US price
A32: Revenue lost per downgrade ($) | B32: =MAX(B31-B27,0) -> 4.11
A33: Paid conversion of free monthly users | C33: 0.005 | D33: 0.01 | E33: 0.015
A35: Option C: scale ads in free Copilot (Microsoft already serves Copilot ads; current yield is not disclosed)
A36: Share of monthly users in ad markets | B36: 0.6 | D36: Assumption
A37: Cannibalisation of Bing search ads | B37: 0.3 | D37: Assumption: some Copilot queries replace Bing queries
A38: Ad serving and operations cost (% of revenue) | B38: 0.15 | D38: Assumption
A39: Ad revenue per user in ad markets per year ($) | C39: 1 | D39: 2 | E39: 3
A40: FY29 ad yield as % of Bing yield | B40: =E39/B14 -> 0.19768055 | D40: Sanity check against Bing
C42: FY27 (Jul 2026-Jun 2027) | D42: FY28 (Jul 2027-Jun 2028) | E42: FY29 (Jul 2028-Jun 2029)
A43: Year index | C43: 1 | D43: 2 | E43: 3
A44: Paid consumer subscribers (M) | C44: =$B$8*(1+$B$9)^C43 -> 90.397895 | D44: =$B$8*(1+$B$9)^D43 -> 94.013811 | E44: =$B$8*(1+$B$9)^E43 -> 97.774363
A45: Free Copilot monthly users (M) | C45: =$B$10*(1+$B$11)^C43 -> 330 | D45: =$B$10*(1+$B$11)^D43 -> 363 | E45: =$B$10*(1+$B$11)^E43 -> 399.3
...

Sheet Sensitivity
A1: Sensitivity: when do the uncertain options beat the safe one?
A2: Values are NPV of gross profit ($M). Green cells beat Option A's NPV. Ramps for FY27 and FY28 scale in proportion to the Business Case inputs.
A4: Option A NPV ($M), for comparison | B4: ='Business Case'!E67 -> 388.18451
A6: Option C: FY29 ad revenue per user (rows) by Bing cannibalisation (columns)
A7: $ per user / cannibalisation | B7: 0.1 | C7: 0.2 | D7: 0.3 | E7: 0.4 | F7: 0.5
A8: 1 | B8: =(('Business Case'!$C$58*$A8*'Business Case'!$C$39/'Business Case'!$E$39)/(1+'Business Case'!$B$12)^1+('Business Case'!$D$58*$A8*'Business Case'!$D$39/'Business Case'!$E$39)/(1+'Business Case'!$B$12)^2+('Business Case'!$E$58*$A8)/(1+'Business Case'!$B$12)^3)*(1-B$7)*(1-'Business Case'!$B$38) -> 281.33802 | C8: =(('Business Case'!$C$58*$A8*'Business Case'!$C$39/'Business Case'!$E$39)/(1+'Business Case'!$B$12)^1+('Business Case'!$D$58*$A8*'Business Case'!$D$39/'Business Case'!$E$39)/(1+'Business Case'!$B$12)^2+('Business Case'!$E$58*$A8)/(1+'Business Case'!$B$12)^3)*(1-C$7)*(1-'Business Case'!$B$38) -> 250.07824 | D8: =(('Business Case'!$C$58*$A8*'Business Case'!$C$39/'Business Case'!$E$39)/(1+'Business Case'!$B$12)^1+('Business Case'!$D$58*$A8*'Business Case'!$D$39/'Business Case'!$E$39)/(1+'Business Case'!$B$12)^2+('Business Case'!$E$58*$A8)/(1+'Business Case'!$B$12)^3)*(1-D$7)*(1-'Business Case'!$B$38) -> 218.81846 | E8: =(('Business Case'!$C$58*$A8*'Business Case'!$C$39/'Business Case'!$E$39)/(1+'Business Case'!$B$12)^1+('Business Case'!$D$58*$A8*'Business Case'!$D$39/'Business Case'!$E$39)/(1+'Business Case'!$B$12)^2+('Business Case'!$E$58*$A8)/(1+'Business Case'!$B$12)^3)*(1-E$7)*(1-'Business Case'!$B$38) -> 187.55868 | F8: =(('Business Case'!$C$58*$A8*'Business Case'!$C$39/'Business Case'!$E$39)/(1+'Business Case'!$B$12)^1+('Business Case'!$D$58*$A8*'Business Case'!$D$39/'Business Case'!$E$39)/(1+'Business Case'!$B$12)^2+('Business Case'!$E$58*$A8)/(1+'Business Case'!$B$12)^3)*(1-F$7)*(1-'Business Case'!$B$38) -> 156.2989
A9: 2 | B9: =(('Business Case'!$C$58*$A9*'Business Case'!$C$39/'Business Case'!$E$39)/(1+'Business Case'!$B$12)^1+('Business Case'!$D$58*$A9*'Business Case'!$D$39/'Business Case'!$E$39)/(1+'Business Case'!$B$12)^2+('Business Case'!$E$58*$A9)/(1+'Business Case'!$B$12)^3)*(1-B$7)*(1-'Business Case'!$B$38) -> 562.67603 | C9: =(('Business Case'!$C$58*$A9*'Business Case'!$C$39/'Business Case'!$E$39)/(1+'Business Case'!$B$12)^1+('Business Case'!$D$58*$A9*'Business Case'!$D$39/'Business Case'!$E$39)/(1+'Business Case'!$B$12)^2+('Business Case'!$E$58*$A9)/(1+'Business Case'!$B$12)^3)*(1-C$7)*(1-'Business Case'!$B$38) -> 500.15647 | D9: =(('Business Case'!$C$58*$A9*'Business Case'!$C$39/'Business Case'!$E$39)/(1+'Business Case'!$B$12)^1+('Business Case'!$D$58*$A9*'Business Case'!$D$39/'Business Case'!$E$39)/(1+'Business Case'!$B$12)^2+('Business Case'!$E$58*$A9)/(1+'Business Case'!$B$12)^3)*(1-D$7)*(1-'Business Case'!$B$38) -> 437.63691 | E9: =(('Business Case'!$C$58*$A9*'Business Case'!$C$39/'Business Case'!$E$39)/(1+'Business Case'!$B$12)^1+('Business Case'!$D$58*$A9*'Business Case'!$D$39/'Business Case'!$E$39)/(1+'Business Case'!$B$12)^2+('Business Case'!$E$58*$A9)/(1+'Business Case'!$B$12)^3)*(1-E$7)*(1-'Business Case'!$B$38) -> 375.11735 | F9: =(('Business Case'!$C$58*$A9*'Business Case'!$C$39/'Business Case'!$E$39)/(1+'Business Case'!$B$12)^1+('Business Case'!$D$58*$A9*'Business Case'!$D$39/'Business Case'!$E$39)/(1+'Business Case'!$B$12)^2+('Business Case'!$E$58*$A9)/(1+'Business Case'!$B$12)^3)*(1-F$7)*(1-'Business Case'!$B$38) -> 312.5978
A10: 3 | B10: =(('Business Case'!$C$58*$A10*'Business Case'!$C$39/'Business Case'!$E$39)/(1+'Business Case'!$B$12)^1+('Business Case'!$D$58*$A10*'Business Case'!$D$39/'Business Case'!$E$39)/(1+'Business Case'!$B$12)^2+('Business Case'!$E$58*$A10)/(1+'Business Case'!$B$12)^3)*(1-B$7)*(1-'Business Case'!$B$38) -> 844.01405 | C10: =(('Business Case'!$C$58*$A10*'Business Case'!$C$39/'Business Case'!$E$39)/(1+'Business Case'!$B$12)^1+('Business Case'!$D$58*$A10*'Business Case'!$D$39/'Business Case'!$E$39)/(1+'Business Case'!$B$12)^2+('Business Case'!$E$58*$A10)/(1+'Business Case'!$B$12)^3)*(1-C$7)*(1-'Business Case'!$B$38) -> 750.23471 | D10: =(('Business Case'!$C$58*$A10*'Business Case'!$C$39/'Business Case'!$E$39)/(1+'Business Case'!$B$12)^1+('Business Case'!$D$58*$A10*'Business Case'!$D$39/'Business Case'!$E$39)/(1+'Business Case'!$B$12)^2+('Business Case'!$E$58*$A10)/(1+'Business Case'!$B$12)^3)*(1-D$7)*(1-'Business Case'!$B$38) -> 656.45537 | E10: =(('Business Case'!$C$58*$A10*'Business Case'!$C$39/'Business Case'!$E$39)/(1+'Business Case'!$B$12)^1+('Business Case'!$D$58*$A10*'Business Case'!$D$39/'Business Case'!$E$39)/(1+'Business Case'!$B$12)^2+('Business Case'!$E$58*$A10)/(1+'Business Case'!$B$12)^3)*(1-E$7)*(1-'Business Case'!$B$38) -> 562.67603 | F10: =(('Business Case'!$C$58*$A10*'Business Case'!$C$39/'Business Case'!$E$39)/(1+'Business Case'!$B$12)^1+('Business Case'!$D$58*$A10*'Business Case'!$D$39/'Business Case'!$E$39)/(1+'Business Case'!$B$12)^2+('Business Case'!$E$58*$A10)/(1+'Business Case'!$B$12)^3)*(1-F$7)*(1-'Business Case'!$B$38) -> 468.89669
A11: 4 | B11: =(('Business Case'!$C$58*$A11*'Business Case'!$C$39/'Business Case'!$E$39)/(1+'Business Case'!$B$12)^1+('Business Case'!$D$58*$A11*'Business Case'!$D$39/'Business Case'!$E$39)/(1+'Business Case'!$B$12)^2+('Business Case'!$E$58*$A11)/(1+'Business Case'!$B$12)^3)*(1-B$7)*(1-'Business Case'!$B$38) -> 1125.3521 | C11: =(('Business Case'!$C$58*$A11*'Business Case'!$C$39/'Business Case'!$E$39)/(1+'Business Case'!$B$12)^1+('Business Case'!$D$58*$A11*'Business Case'!$D$39/'Business Case'!$E$39)/(1+'Business Case'!$B$12)^2+('Business Case'!$E$58*$A11)/(1+'Business Case'!$B$12)^3)*(1-C$7)*(1-'Business Case'!$B$38) -> 1000.3129 | D11: =(('Business Case'!$C$58*$A11*'Business Case'!$C$39/'Business Case'!$E$39)/(1+'Business Case'!$B$12)^1+('Business Case'!$D$58*$A11*'Business Case'!$D$39/'Business Case'!$E$39)/(1+'Business Case'!$B$12)^2+('Business Case'!$E$58*$A11)/(1+'Business Case'!$B$12)^3)*(1-D$7)*(1-'Business Case'!$B$38) -> 875.27383 | E11: =(('Business Case'!$C$58*$A11*'Business Case'!$C$39/'Business Case'!$E$39)/(1+'Business Case'!$B$12)^1+('Business Case'!$D$58*$A11*'Business Case'!$D$39/'Business Case'!$E$39)/(1+'Business Case'!$B$12)^2+('Business Case'!$E$58*$A11)/(1+'Business Case'!$B$12)^3)*(1-E$7)*(1-'Business Case'!$B$38) -> 750.23471 | F11: =(('Business Case'!$C$58*$A11*'Business Case'!$C$39/'Business Case'!$E$39)/(1+'Business Case'!$B$12)^1+('Business Case'!$D$58*$A11*'Business Case'!$D$39/'Business Case'!$E$39)/(1+'Business Case'!$B$12)^2+('Business Case'!$E$58*$A11)/(1+'Business Case'!$B$12)^3)*(1-F$7)*(1-'Business Case'!$B$38) -> 625.19559
A12: 5 | B12: =(('Business Case'!$C$58*$A12*'Business Case'!$C$39/'Business Case'!$E$39)/(1+'Business Case'!$B$12)^1+('Business Case'!$D$58*$A12*'Business Case'!$D$39/'Business Case'!$E$39)/(1+'Business Case'!$B$12)^2+('Business Case'!$E$58*$A12)/(1+'Business Case'!$B$12)^3)*(1-B$7)*(1-'Business Case'!$B$38) -> 1406.6901 | C12: =(('Business Case'!$C$58*$A12*'Business Case'!$C$39/'Business Case'!$E$39)/(1+'Business Case'!$B$12)^1+('Business Case'!$D$58*$A12*'Business Case'!$D$39/'Business Case'!$E$39)/(1+'Business Case'!$B$12)^2+('Business Case'!$E$58*$A12)/(1+'Business Case'!$B$12)^3)*(1-C$7)*(1-'Business Case'!$B$38) -> 1250.3912 | D12: =(('Business Case'!$C$58*$A12*'Business Case'!$C$39/'Business Case'!$E$39)/(1+'Business Case'!$B$12)^1+('Business Case'!$D$58*$A12*'Business Case'!$D$39/'Business Case'!$E$39)/(1+'Business Case'!$B$12)^2+('Business Case'!$E$58*$A12)/(1+'Business Case'!$B$12)^3)*(1-D$7)*(1-'Business Case'!$B$38) -> 1094.0923 | E12: =(('Business Case'!$C$58*$A12*'Business Case'!$C$39/'Business Case'!$E$39)/(1+'Business Case'!$B$12)^1+('Business Case'!$D$58*$A12*'Business Case'!$D$39/'Business Case'!$E$39)/(1+'Business Case'!$B$12)^2+('Business Case'!$E$58*$A12)/(1+'Business Case'!$B$12)^3)*(1-E$7)*(1-'Business Case'!$B$38) -> 937.79339 | F12: =(('Business Case'!$C$58*$A12*'Business Case'!$C$39/'Business Case'!$E$39)/(1+'Business Case'!$B$12)^1+('Business Case'!$D$58*$A12*'Business Case'!$D$39/'Business Case'!$E$39)/(1+'Business Case'!$B$12)^2+('Business Case'!$E$58*$A12)/(1+'Business Case'!$B$12)^3)*(1-F$7)*(1-'Business Case'!$B$38) -> 781.49449
A15: Option B: FY29 paid conversion (rows) by monthly price (columns)
A16: Conversion / price | B16: 4.99 | C16: 7.99 | D16: 9.99 | E16: 12.99
A17: 0.005 | B17: =(('Business Case'!$C$45*$A17*'Business Case'!$C$33/'Business Case'!$E$33)*(B$16*12-'Business Case'!$B$30*MAX('Business Case'!$B$31-B$16*12,0)-'Business Case'!$B$28)-('Business Case'!$C$45*$A17*'Business Case'!$C$33/'Business Case'!$E$33)*'Business Case'!$B$29)/(1+'Business Case'!$B$12)+(('Business Case'!$D$45*$A17*'Business Case'!$D$33/'Business Case'!$E$33)*(B$16*12-'Business Case'!$B$30*MAX('Business Case'!$B$31-B$16*12,0)-'Business Case'!$B$28)-MAX(('Business Case'!$D$45*$A17*'Business Case'!$D$33/'Business Case'!$E$33)-('Business Case'!$C$45*$A17*'Business Case'!$C$33/'Business Case'!$E$33),0)*'Business Case'!$B$29)/(1+'Business Case'!$B$12)^2+(('Business Case'!$E$45*$A17)*(B$16*12-'Business Case'!$B$30*MAX('Business Case'!$B$31-B$16*12,0)-'Business Case'!$B$28)-MAX(('Business Case'!$E$45*$A17)-('Business Case'!$D$45*$A17*'Business Case'!$D$33/'Business Case'!$E$33),0)*'Business Case'!$B$29)/(1+'Business Case'!$B$12)^3 -> 33.639504 | C17: =(('Business Case'!$C$45*$A17*'Business Case'!$C$33/'Business Case'!$E$33)*(C$16*12-'Business Case'!$B$30*MAX('Business Case'!$B$31-C$16*12,0)-'Business Case'!$B$28)-('Business Case'!$C$45*$A17*'Business Case'!$C$33/'Business Case'!$E$33)*'Business Case'!$B$29)/(1+'Business Case'!$B$12)+(('Business Case'!$D$45*$A17*'Business Case'!$D$33/'Business Case'!$E$33)*(C$16*12-'Business Case'!$B$30*MAX('Business Case'!$B$31-C$16*12,0)-'Business Case'!$B$28)-MAX(('Business Case'!$D$45*$A17*'Business Case'!$D$33/'Business Case'!$E$33)-('Business Case'!$C$45*$A17*'Business Case'!$C$33/'Business Case'!$E$33),0)*'Business Case'!$B$29)/(1+'Business Case'!$B$12)^2+(('Business Case'!$E$45*$A17)*(C$16*12-'Business Case'!$B$30*MAX('Business Case'!$B$31-C$16*12,0)-'Business Case'!$B$28)-MAX(('Business Case'!$E$45*$A17)-('Business Case'!$D$45*$A17*'Business Case'!$D$33/'Business Case'!$E$33),0)*'Business Case'!$B$29)/(1+'Business Case'!$B$12)^3 -> 166.03386 | D17: =(('Business Case'!$C$45*$A17*'Business Case'!$C$33/'Business Case'!$E$33)*(D$16*12-'Business Case'!$B$30*MAX('Business Case'!$B$31-D$16*12,0)-'Business Case'!$B$28)-('Business Case'!$C$45*$A17*'Business Case'!$C$33/'Business Case'!$E$33)*'Business Case'!$B$29)/(1+'Business Case'!$B$12)+(('Business Case'!$D$45*$A17*'Business Case'!$D$33/'Business Case'!$E$33)*(D$16*12-'Business Case'!$B$30*MAX('Business Case'!$B$31-D$16*12,0)-'Business Case'!$B$28)-MAX(('Business Case'!$D$45*$A17*'Business Case'!$D$33/'Business Case'!$E$33)-('Business Case'!$C$45*$A17*'Business Case'!$C$33/'Business Case'!$E$33),0)*'Business Case'!$B$29)/(1+'Business Case'!$B$12)^2+(('Business Case'!$E$45*$A17)*(D$16*12-'Business Case'!$B$30*MAX('Business Case'!$B$31-D$16*12,0)-'Business Case'!$B$28)-MAX(('Business Case'!$E$45*$A17)-('Business Case'!$D$45*$A17*'Business Case'!$D$33/'Business Case'!$E$33),0)*'Business Case'!$B$29)/(1+'Business Case'!$B$12)^3 -> 242.10546 | E17: =(('Business Case'!$C$45*$A17*'Business Case'!$C$33/'Business Case'!$E$33)*(E$16*12-'Business Case'!$B$30*MAX('Business Case'!$B$31-E$16*12,0)-'Business Case'!$B$28)-('Business Case'!$C$45*$A17*'Business Case'!$C$33/'Business Case'!$E$33)*'Business Case'!$B$29)/(1+'Business Case'!$B$12)+(('Business Case'!$D$45*$A17*'Business Case'!$D$33/'Business Case'!$E$33)*(E$16*12-'Business Case'!$B$30*MAX('Business Case'!$B$31-E$16*12,0)-'Business Case'!$B$28)-MAX(('Business Case'!$D$45*$A17*'Business Case'!$D$33/'Business Case'!$E$33)-('Business Case'!$C$45*$A17*'Business Case'!$C$33/'Business Case'!$E$33),0)*'Business Case'!$B$29)/(1+'Business Case'!$B$12)^2+(('Business Case'!$E$45*$A17)*(E$16*12-'Business Case'!$B$30*MAX('Business Case'!$B$31-E$16*12,0)-'Business Case'!$B$28)-MAX(('Business Case'!$E$45*$A17)-('Business Case'!$D$45*$A17*'Business Case'!$D$33/'Business Case'!$E$33),0)*'Business Case'!$B$29)/(1+'Business Case'!$B$12)^3 -> 352.43409
A18: 0.01 | B18: =(('Business Case'!$C$45*$A18*'Business Case'!$C$33/'Business Case'!$E$33)*(B$16*12-'Business Case'!$B$30*MAX('Business Case'!$B$31-B$16*12,0)-'Business Case'!$B$28)-('Business Case'!$C$45*$A18*'Business Case'!$C$33/'Business Case'!$E$33)*'Business Case'!$B$29)/(1+'Business Case'!$B$12)+(('Business Case'!$D$45*$A18*'Business Case'!$D$33/'Business Case'!$E$33)*(B$16*12-'Business Case'!$B$30*MAX('Business Case'!$B$31-B$16*12,0)-'Business Case'!$B$28)-MAX(('Business Case'!$D$45*$A18*'Business Case'!$D$33/'Business Case'!$E$33)-('Business Case'!$C$45*$A18*'Business Case'!$C$33/'Business Case'!$E$33),0)*'Business Case'!$B$29)/(1+'Business Case'!$B$12)^2+(('Business Case'!$E$45*$A18)*(B$16*12-'Business Case'!$B$30*MAX('Business Case'!$B$31-B$16*12,0)-'Business Case'!$B$28)-MAX(('Business Case'!$E$45*$A18)-('Business Case'!$D$45*$A18*'Business Case'!$D$33/'Business Case'!$E$33),0)*'Business Case'!$B$29)/(1+'Business Case'!$B$12)^3 -> 67.279007 | C18: =(('Business Case'!$C$45*$A18*'Business Case'!$C$33/'Business Case'!$E$33)*(C$16*12-'Business Case'!$B$30*MAX('Business Case'!$B$31-C$16*12,0)-'Business Case'!$B$28)-('Business Case'!$C$45*$A18*'Business Case'!$C$33/'Business Case'!$E$33)*'Business Case'!$B$29)/(1+'Business Case'!$B$12)+(('Business Case'!$D$45*$A18*'Business Case'!$D$33/'Business Case'!$E$33)*(C$16*12-'Business Case'!$B$30*MAX('Business Case'!$B$31-C$16*12,0)-'Business Case'!$B$28)-MAX(('Business Case'!$D$45*$A18*'Business Case'!$D$33/'Business Case'!$E$33)-('Business Case'!$C$45*$A18*'Business Case'!$C$33/'Business Case'!$E$33),0)*'Business Case'!$B$29)/(1+'Business Case'!$B$12)^2+(('Business Case'!$E$45*$A18)*(C$16*12-'Business Case'!$B$30*MAX('Business Case'!$B$31-C$16*12,0)-'Business Case'!$B$28)-MAX(('Business Case'!$E$45*$A18)-('Business Case'!$D$45*$A18*'Business Case'!$D$33/'Business Case'!$E$33),0)*'Business Case'!$B$29)/(1+'Business Case'!$B$12)^3 -> 332.06773 | D18: =(('Business Case'!$C$45*$A18*'Business Case'!$C$33/'Business Case'!$E$33)*(D$16*12-'Business Case'!$B$30*MAX('Business Case'!$B$31-D$16*12,0)-'Business Case'!$B$28)-('Business Case'!$C$45*$A18*'Business Case'!$C$33/'Business Case'!$E$33)*'Business Case'!$B$29)/(1+'Business Case'!$B$12)+(('Business Case'!$D$45*$A18*'Business Case'!$D$33/'Business Case'!$E$33)*(D$16*12-'Business Case'!$B$30*MAX('Business Case'!$B$31-D$16*12,0)-'Business Case'!$B$28)-MAX(('Business Case'!$D$45*$A18*'Business Case'!$D$33/'Business Case'!$E$33)-('Business Case'!$C$45*$A18*'Business Case'!$C$33/'Business Case'!$E$33),0)*'Business Case'!$B$29)/(1+'Business Case'!$B$12)^2+(('Business Case'!$E$45*$A18)*(D$16*12-'Business Case'!$B$30*MAX('Business Case'!$B$31-D$16*12,0)-'Business Case'!$B$28)-MAX(('Business Case'!$E$45*$A18)-('Business Case'!$D$45*$A18*'Business Case'!$D$33/'Business Case'!$E$33),0)*'Business Case'!$B$29)/(1+'Business Case'!$B$12)^3 -> 484.21091 | E18: =(('Business Case'!$C$45*$A18*'Business Case'!$C$33/'Business Case'!$E$33)*(E$16*12-'Business Case'!$B$30*MAX('Business Case'!$B$31-E$16*12,0)-'Business Case'!$B$28)-('Business Case'!$C$45*$A18*'Business Case'!$C$33/'Business Case'!$E$33)*'Business Case'!$B$29)/(1+'Business Case'!$B$12)+(('Business Case'!$D$45*$A18*'Business Case'!$D$33/'Business Case'!$E$33)*(E$16*12-'Business Case'!$B$30*MAX('Business Case'!$B$31-E$16*12,0)-'Business Case'!$B$28)-MAX(('Business Case'!$D$45*$A18*'Business Case'!$D$33/'Business Case'!$E$33)-('Business Case'!$C$45*$A18*'Business Case'!$C$33/'Business Case'!$E$33),0)*'Business Case'!$B$29)/(1+'Business Case'!$B$12)^2+(('Business Case'!$E$45*$A18)*(E$16*12-'Business Case'!$B$30*MAX('Business Case'!$B$31-E$16*12,0)-'Business Case'!$B$28)-MAX(('Business Case'!$E$45*$A18)-('Business Case'!$D$45*$A18*'Business Case'!$D$33/'Business Case'!$E$33),0)*'Business Case'!$B$29)/(1+'Business Case'!$B$12)^3 -> 704.86818
A19: 0.015 | B19: =(('Business Case'!$C$45*$A19*'Business Case'!$C$33/'Business Case'!$E$33)*(B$16*12-'Business Case'!$B$30*MAX('Business Case'!$B$31-B$16*12,0)-'Business Case'!$B$28)-('Business Case'!$C$45*$A19*'Business Case'!$C$33/'Business Case'!$E$33)*'Business Case'!$B$29)/(1+'Business Case'!$B$12)+(('Business Case'!$D$45*$A19*'Business Case'!$D$33/'Business Case'!$E$33)*(B$16*12-'Business Case'!$B$30*MAX('Business Case'!$B$31-B$16*12,0)-'Business Case'!$B$28)-MAX(('Business Case'!$D$45*$A19*'Business Case'!$D$33/'Business Case'!$E$33)-('Business Case'!$C$45*$A19*'Business Case'!$C$33/'Business Case'!$E$33),0)*'Business Case'!$B$29)/(1+'Business Case'!$B$12)^2+(('Business Case'!$E$45*$A19)*(B$16*12-'Business Case'!$B$30*MAX('Business Case'!$B$31-B$16*12,0)-'Business Case'!$B$28)-MAX(('Business Case'!$E$45*$A19)-('Business Case'!$D$45*$A19*'Business Case'!$D$33/'Business Case'!$E$33),0)*'Business Case'!$B$29)/(1+'Business Case'!$B$12)^3 -> 100.91851 | C19: =(('Business Case'!$C$45*$A19*'Business Case'!$C$33/'Business Case'!$E$33)*(C$16*12-'Business Case'!$B$30*MAX('Business Case'!$B$31-C$16*12,0)-'Business Case'!$B$28)-('Business Case'!$C$45*$A19*'Business Case'!$C$33/'Business Case'!$E$33)*'Business Case'!$B$29)/(1+'Business Case'!$B$12)+(('Business Case'!$D$45*$A19*'Business Case'!$D$33/'Business Case'!$E$33)*(C$16*12-'Business Case'!$B$30*MAX('Business Case'!$B$31-C$16*12,0)-'Business Case'!$B$28)-MAX(('Business Case'!$D$45*$A19*'Business Case'!$D$33/'Business Case'!$E$33)-('Business Case'!$C$45*$A19*'Business Case'!$C$33/'Business Case'!$E$33),0)*'Business Case'!$B$29)/(1+'Business Case'!$B$12)^2+(('Business Case'!$E$45*$A19)*(C$16*12-'Business Case'!$B$30*MAX('Business Case'!$B$31-C$16*12,0)-'Business Case'!$B$28)-MAX(('Business Case'!$E$45*$A19)-('Business Case'!$D$45*$A19*'Business Case'!$D$33/'Business Case'!$E$33),0)*'Business Case'!$B$29)/(1+'Business Case'!$B$12)^3 -> 498.10159 | D19: =(('Business Case'!$C$45*$A19*'Business Case'!$C$33/'Business Case'!$E$33)*(D$16*12-'Business Case'!$B$30*MAX('Business Case'!$B$31-D$16*12,0)-'Business Case'!$B$28)-('Business Case'!$C$45*$A19*'Business Case'!$C$33/'Business Case'!$E$33)*'Business Case'!$B$29)/(1+'Business Case'!$B$12)+(('Business Case'!$D$45*$A19*'Business Case'!$D$33/'Business Case'!$E$33)*(D$16*12-'Business Case'!$B$30*MAX('Business Case'!$B$31-D$16*12,0)-'Business Case'!$B$28)-MAX(('Business Case'!$D$45*$A19*'Business Case'!$D$33/'Business Case'!$E$33)-('Business Case'!$C$45*$A19*'Business Case'!$C$33/'Business Case'!$E$33),0)*'Business Case'!$B$29)/(1+'Business Case'!$B$12)^2+(('Business Case'!$E$45*$A19)*(D$16*12-'Business Case'!$B$30*MAX('Business Case'!$B$31-D$16*12,0)-'Business Case'!$B$28)-MAX(('Business Case'!$E$45*$A19)-('Business Case'!$D$45*$A19*'Business Case'!$D$33/'Business Case'!$E$33),0)*'Business Case'!$B$29)/(1+'Business Case'!$B$12)^3 -> 726.31637 | E19: =(('Business Case'!$C$45*$A19*'Business Case'!$C$33/'Business Case'!$E$33)*(E$16*12-'Business Case'!$B$30*MAX('Business Case'!$B$31-E$16*12,0)-'Business Case'!$B$28)-('Business Case'!$C$45*$A19*'Business Case'!$C$33/'Business Case'!$E$33)*'Business Case'!$B$29)/(1+'Business Case'!$B$12)+(('Business Case'!$D$45*$A19*'Business Case'!$D$33/'Business Case'!$E$33)*(E$16*12-'Business Case'!$B$30*MAX('Business Case'!$B$31-E$16*12,0)-'Business Case'!$B$28)-MAX(('Business Case'!$D$45*$A19*'Business Case'!$D$33/'Business Case'!$E$33)-('Business Case'!$C$45*$A19*'Business Case'!$C$33/'Business Case'!$E$33),0)*'Business Case'!$B$29)/(1+'Business Case'!$B$12)^2+(('Business Case'!$E$45*$A19)*(E$16*12-'Business Case'!$B$30*MAX('Business Case'!$B$31-E$16*12,0)-'Business Case'!$B$28)-MAX(('Business Case'!$E$45*$A19)-('Business Case'!$D$45*$A19*'Business Case'!$D$33/'Business Case'!$E$33),0)*'Business Case'!$B$29)/(1+'Business Case'!$B$12)^3 -> 1057.3023
A20: 0.02 | B20: =(('Business Case'!$C$45*$A20*'Business Case'!$C$33/'Business Case'!$E$33)*(B$16*12-'Business Case'!$B$30*MAX('Business Case'!$B$31-B$16*12,0)-'Business Case'!$B$28)-('Business Case'!$C$45*$A20*'Business Case'!$C$33/'Business Case'!$E$33)*'Business Case'!$B$29)/(1+'Business Case'!$B$12)+(('Business Case'!$D$45*$A20*'Business Case'!$D$33/'Business Case'!$E$33)*(B$16*12-'Business Case'!$B$30*MAX('Business Case'!$B$31-B$16*12,0)-'Business Case'!$B$28)-MAX(('Business Case'!$D$45*$A20*'Business Case'!$D$33/'Business Case'!$E$33)-('Business Case'!$C$45*$A20*'Business Case'!$C$33/'Business Case'!$E$33),0)*'Business Case'!$B$29)/(1+'Business Case'!$B$12)^2+(('Business Case'!$E$45*$A20)*(B$16*12-'Business Case'!$B$30*MAX('Business Case'!$B$31-B$16*12,0)-'Business Case'!$B$28)-MAX(('Business Case'!$E$45*$A20)-('Business Case'!$D$45*$A20*'Business Case'!$D$33/'Business Case'!$E$33),0)*'Business Case'!$B$29)/(1+'Business Case'!$B$12)^3 -> 134.55801 | C20: =(('Business Case'!$C$45*$A20*'Business Case'!$C$33/'Business Case'!$E$33)*(C$16*12-'Business Case'!$B$30*MAX('Business Case'!$B$31-C$16*12,0)-'Business Case'!$B$28)-('Business Case'!$C$45*$A20*'Business Case'!$C$33/'Business Case'!$E$33)*'Business Case'!$B$29)/(1+'Business Case'!$B$12)+(('Business Case'!$D$45*$A20*'Business Case'!$D$33/'Business Case'!$E$33)*(C$16*12-'Business Case'!$B$30*MAX('Business Case'!$B$31-C$16*12,0)-'Business Case'!$B$28)-MAX(('Business Case'!$D$45*$A20*'Business Case'!$D$33/'Business Case'!$E$33)-('Business Case'!$C$45*$A20*'Business Case'!$C$33/'Business Case'!$E$33),0)*'Business Case'!$B$29)/(1+'Business Case'!$B$12)^2+(('Business Case'!$E$45*$A20)*(C$16*12-'Business Case'!$B$30*MAX('Business Case'!$B$31-C$16*12,0)-'Business Case'!$B$28)-MAX(('Business Case'!$E$45*$A20)-('Business Case'!$D$45*$A20*'Business Case'!$D$33/'Business Case'!$E$33),0)*'Business Case'!$B$29)/(1+'Business Case'!$B$12)^3 -> 664.13546 | D20: =(('Business Case'!$C$45*$A20*'Business Case'!$C$33/'Business Case'!$E$33)*(D$16*12-'Business Case'!$B$30*MAX('Business Case'!$B$31-D$16*12,0)-'Business Case'!$B$28)-('Business Case'!$C$45*$A20*'Business Case'!$C$33/'Business Case'!$E$33)*'Business Case'!$B$29)/(1+'Business Case'!$B$12)+(('Business Case'!$D$45*$A20*'Business Case'!$D$33/'Business Case'!$E$33)*(D$16*12-'Business Case'!$B$30*MAX('Business Case'!$B$31-D$16*12,0)-'Business Case'!$B$28)-MAX(('Business Case'!$D$45*$A20*'Business Case'!$D$33/'Business Case'!$E$33)-('Business Case'!$C$45*$A20*'Business Case'!$C$33/'Business Case'!$E$33),0)*'Business Case'!$B$29)/(1+'Business Case'!$B$12)^2+(('Business Case'!$E$45*$A20)*(D$16*12-'Business Case'!$B$30*MAX('Business Case'!$B$31-D$16*12,0)-'Business Case'!$B$28)-MAX(('Business Case'!$E$45*$A20)-('Business Case'!$D$45*$A20*'Business Case'!$D$33/'Business Case'!$E$33),0)*'Business Case'!$B$29)/(1+'Business Case'!$B$12)^3 -> 968.42183 | E20: =(('Business Case'!$C$45*$A20*'Business Case'!$C$33/'Business Case'!$E$33)*(E$16*12-'Business Case'!$B$30*MAX('Business Case'!$B$31-E$16*12,0)-'Business Case'!$B$28)-('Business Case'!$C$45*$A20*'Business Case'!$C$33/'Business Case'!$E$33)*'Business Case'!$B$29)/(1+'Business Case'!$B$12)+(('Business Case'!$D$45*$A20*'Business Case'!$D$33/'Business Case'!$E$33)*(E$16*12-'Business Case'!$B$30*MAX('Business Case'!$B$31-E$16*12,0)-'Business Case'!$B$28)-MAX(('Business Case'!$D$45*$A20*'Business Case'!$D$33/'Business Case'!$E$33)-('Business Case'!$C$45*$A20*'Business Case'!$C$33/'Business Case'!$E$33),0)*'Business Case'!$B$29)/(1+'Business Case'!$B$12)^2+(('Business Case'!$E$45*$A20)*(E$16*12-'Business Case'!$B$30*MAX('Business Case'!$B$31-E$16*12,0)-'Business Case'!$B$28)-MAX(('Business Case'!$E$45*$A20)-('Business Case'!$D$45*$A20*'Business Case'!$D$33/'Business Case'!$E$33),0)*'Business Case'!$B$29)/(1+'Business Case'!$B$12)^3 -> 1409.7364
A21: 0.03 | B21: =(('Business Case'!$C$45*$A21*'Business Case'!$C$33/'Business Case'!$E$33)*(B$16*12-'Business Case'!$B$30*MAX('Business Case'!$B$31-B$16*12,0)-'Business Case'!$B$28)-('Business Case'!$C$45*$A21*'Business Case'!$C$33/'Business Case'!$E$33)*'Business Case'!$B$29)/(1+'Business Case'!$B$12)+(('Business Case'!$D$45*$A21*'Business Case'!$D$33/'Business Case'!$E$33)*(B$16*12-'Business Case'!$B$30*MAX('Business Case'!$B$31-B$16*12,0)-'Business Case'!$B$28)-MAX(('Business Case'!$D$45*$A21*'Business Case'!$D$33/'Business Case'!$E$33)-('Business Case'!$C$45*$A21*'Business Case'!$C$33/'Business Case'!$E$33),0)*'Business Case'!$B$29)/(1+'Business Case'!$B$12)^2+(('Business Case'!$E$45*$A21)*(B$16*12-'Business Case'!$B$30*MAX('Business Case'!$B$31-B$16*12,0)-'Business Case'!$B$28)-MAX(('Business Case'!$E$45*$A21)-('Business Case'!$D$45*$A21*'Business Case'!$D$33/'Business Case'!$E$33),0)*'Business Case'!$B$29)/(1+'Business Case'!$B$12)^3 -> 201.83702 | C21: =(('Business Case'!$C$45*$A21*'Business Case'!$C$33/'Business Case'!$E$33)*(C$16*12-'Business Case'!$B$30*MAX('Business Case'!$B$31-C$16*12,0)-'Business Case'!$B$28)-('Business Case'!$C$45*$A21*'Business Case'!$C$33/'Business Case'!$E$33)*'Business Case'!$B$29)/(1+'Business Case'!$B$12)+(('Business Case'!$D$45*$A21*'Business Case'!$D$33/'Business Case'!$E$33)*(C$16*12-'Business Case'!$B$30*MAX('Business Case'!$B$31-C$16*12,0)-'Business Case'!$B$28)-MAX(('Business Case'!$D$45*$A21*'Business Case'!$D$33/'Business Case'!$E$33)-('Business Case'!$C$45*$A21*'Business Case'!$C$33/'Business Case'!$E$33),0)*'Business Case'!$B$29)/(1+'Business Case'!$B$12)^2+(('Business Case'!$E$45*$A21)*(C$16*12-'Business Case'!$B$30*MAX('Business Case'!$B$31-C$16*12,0)-'Business Case'!$B$28)-MAX(('Business Case'!$E$45*$A21)-('Business Case'!$D$45*$A21*'Business Case'!$D$33/'Business Case'!$E$33),0)*'Business Case'!$B$29)/(1+'Business Case'!$B$12)^3 -> 996.20318 | D21: =(('Business Case'!$C$45*$A21*'Business Case'!$C$33/'Business Case'!$E$33)*(D$16*12-'Business Case'!$B$30*MAX('Business Case'!$B$31-D$16*12,0)-'Business Case'!$B$28)-('Business Case'!$C$45*$A21*'Business Case'!$C$33/'Business Case'!$E$33)*'Business Case'!$B$29)/(1+'Business Case'!$B$12)+(('Business Case'!$D$45*$A21*'Business Case'!$D$33/'Business Case'!$E$33)*(D$16*12-'Business Case'!$B$30*MAX('Business Case'!$B$31-D$16*12,0)-'Business Case'!$B$28)-MAX(('Business Case'!$D$45*$A21*'Business Case'!$D$33/'Business Case'!$E$33)-('Business Case'!$C$45*$A21*'Business Case'!$C$33/'Business Case'!$E$33),0)*'Business Case'!$B$29)/(1+'Business Case'!$B$12)^2+(('Business Case'!$E$45*$A21)*(D$16*12-'Business Case'!$B$30*MAX('Business Case'!$B$31-D$16*12,0)-'Business Case'!$B$28)-MAX(('Business Case'!$E$45*$A21)-('Business Case'!$D$45*$A21*'Business Case'!$D$33/'Business Case'!$E$33),0)*'Business Case'!$B$29)/(1+'Business Case'!$B$12)^3 -> 1452.6327 | E21: =(('Business Case'!$C$45*$A21*'Business Case'!$C$33/'Business Case'!$E$33)*(E$16*12-'Business Case'!$B$30*MAX('Business Case'!$B$31-E$16*12,0)-'Business Case'!$B$28)-('Business Case'!$C$45*$A21*'Business Case'!$C$33/'Business Case'!$E$33)*'Business Case'!$B$29)/(1+'Business Case'!$B$12)+(('Business Case'!$D$45*$A21*'Business Case'!$D$33/'Business Case'!$E$33)*(E$16*12-'Business Case'!$B$30*MAX('Business Case'!$B$31-E$16*12,0)-'Business Case'!$B$28)-MAX(('Business Case'!$D$45*$A21*'Business Case'!$D$33/'Business Case'!$E$33)-('Business Case'!$C$45*$A21*'Business Case'!$C$33/'Business Case'!$E$33),0)*'Business Case'!$B$29)/(1+'Business Case'!$B$12)^2+(('Business Case'!$E$45*$A21)*(E$16*12-'Business Case'!$B$30*MAX('Business Case'!$B$31-E$16*12,0)-'Business Case'!$B$28)-MAX(('Business Case'!$E$45*$A21)-('Business Case'!$D$45*$A21*'Business Case'!$D$33/'Business Case'!$E$33),0)*'Business Case'!$B$29)/(1+'Business Case'!$B$12)^3 -> 2114.6045
A22: Price and conversion are set independently here. In practice a higher price lowers conversion, so compare realistic pairs (for example 1.5% at $7.99 against 0.8% at $12.99).
A23: Check: base case cells should equal the Business Case NPVs
A24: Option C at $3.00 and 30% (should match Business Case E69) | B24: =D10 -> 656.45537 | C24: ='Business Case'!E69 -> 656.45537
A25: Option B at 1.5% and $7.99 (should match Business Case E68) | B25: =C19 -> 498.10159 | C25: ='Business Case'!E68 -> 498.10159

Sheet Sources
A1: Sources
A3: Item | B3: Source
A4: Quarterly revenue by business line, FY25 Q1 to FY26 Q4; restated segments; FY27 Q1 adjusted outlook | B4: Microsoft Form 8-K Exhibit 99.1, FY27 Segments and Investor Metrics, September 2026: https://www.sec.gov/Archives/edgar/data/789019/000119312526380280/d291965dex991.htm
A5: FY26 Q4 results, FY27 Q1 outlook | B5: Microsoft FY26 Q4 earnings release: https://microsoft.com/en-us/investor/earnings/fy-2026-q4/press-release-webcast
A6: Search ex-TAC growth FY26 Q2 (10%) and Q3 (12%) | B6: Microsoft 8-K earnings releases, Jan 28 and Apr 29, 2026 (SEC EDGAR)
A7: Guidance wording, FY26 Q1 to FY26 Q4 and FY27 Q1; consumer cloud and subscription growth, FY26 Q2 | B7: Microsoft earnings call transcripts: FY25 Q4 (Jul 30, 2025) https://www.microsoft.com/en-us/investor/events/fy-2025/earnings-fy-2025-q4 ; FY26 Q1 (Oct 29, 2025) https://www.microsoft.com/en-us/investor/events/fy-2026/earnings-fy-2026-q1 ; FY26 Q2 (Jan 28, 2026) https://www.microsoft.com/en-us/investor/events/fy-2026/earnings-fy-2026-q2 ; FY26 Q3 (Apr 29, 2026) https://www.microsoft.com/en-us/investor/events/fy-2026/earnings-fy-2026-q3 ; FY26 Q4 (Jul 29, 2026) https://www.microsoft.com/en-us/investor/events/fy-2026/earnings-fy-2026-q4
A8: Guidance: FY25 Q4 'high teens' | B8: PPC Land, FY25 Q3 earnings coverage: https://ppc.land/microsoft-ad-revenue-tops-20-billion-as-copilot-transforms-search/
A9: Guidance: FY26 Q1 'low- to mid-teens'; FY25 Q4 actual 21% | B9: PPC Land, FY25 Q4 coverage: https://ppc.land/microsoft-search-advertising-revenue-climbs-21-in-record-quarter/
A10: Guidance: FY26 Q4 'high single digits'; Bing 1B monthly users | B10: Search Engine Journal: https://www.searchenginejournal.com/microsoft-says-bing-reached-1b-monthly-active-users/573444/
A11: Microsoft 365 consumer subscriber count no longer disclosed (from FY26 Q1) | B11: Microsoft Form 10-Q, quarter ended March 31, 2026 (SEC EDGAR)
A12: Microsoft 365 Personal $99.99, Family $129.99, Premium $199.99 per year; Copilot Pro retired | B12: https://www.digitalcitizen.life/microsoft-365-personal-and-family-plans-see-a-price-increase-with-copilot-ai/ and https://office-watch.com/2025/microsoft-365-premium-features-pricing/
A13: ChatGPT Go $8, Google AI Plus $7.99, $20 tiers | B13: https://aizolo.com/blog/chatgpt-vs-claude-vs-gemini-cost-the-2025-ultimate-price-comparison-spoiler-theres-a-better-way/
A14: ChatGPT ~50M paying subscribers, ~900M weekly users; ads on Free and Go tiers from Feb 2026 | B14: https://intuitionlabs.ai/articles/chatgpt-ads-economic-analysis
... A16: All other inputs | B16: Analyst assumptions, marked in blue on the Business Case tab
